# from logging import Logger
import logging
from functools import wraps
import asyncio
import time
import random


def retry_async(
    exceptions: tuple = (Exception,),
    retries=3,
    delay=1,
    fallback=None,
    backoff=2,
    logger: logging.Logger = None,
):
    """
    Retry an asynchronous function call upon encountering a specific exception.

    :param exceptions: The exceptions to catch and retry on.
    :param retries: Number of retry attempts (default is 3).
    :param delay: Delay between retries in seconds (default is 1 second).
    :param fallback: Value to return if retries are exhausted (default is None).
    """

    def decorator(func):
        @wraps(func)
        async def wrapper(*args, **kwargs):
            exp_delay = delay
            for attempt in range(retries):
                try:
                    return await func(*args, **kwargs)
                except exceptions as e:
                    message = f"Attempt {attempt + 1} Failed. {e} Trying again in {exp_delay} seconds"
                    if logger:
                        
                        logger.critical(message)
                    else:
                        print(message)
                    # print(f"Attempt {attempt + 1} failed: {e} Trying again in {exp_delay} seconds")
                    if attempt < retries - 1:
                        await asyncio.sleep(exp_delay)
                        exp_delay = exp_delay**backoff + abs(
                            random.normalvariate(0, 1.2)
                        )
                    else:
                        if fallback is not None:
                            message = "Retries exhausted. Returning fallback value. "
                            if logger:
                                logger.error(message)
                            else:
                                print(message)
                            return fallback
                        else:
                            raise

        return wrapper

    return decorator


def retry_sync(
    exceptions: tuple = (Exception,), retries=3, delay=1, fallback=None, backoff=1.17
):
    """
    Retry a function call upon encountering a specific exception.

    :param exception: The exception to catch and retry on.
    :param retries: Number of retry attempts (default is 3).
    :param delay: Delay between retries in seconds (default is 1 second).
    :param fallback: Value to return if retries are exhausted (default is None).
    """

    def decorator(func):
        @wraps(func)
        def wrapper(*args, **kwargs):
            # backoff_factor = backoff
            exp_delay = delay
            for attempt in range(retries):
                try:
                    return func(*args, **kwargs)
                except exceptions as e:
                    print(
                        f"Attempt {attempt + 1} failed executing {func.__name__}: {e} Trying again in {exp_delay} seconds"
                    )
                    if attempt < retries - 1:
                        time.sleep(exp_delay)
                        exp_delay = exp_delay**backoff + random.random()
                    else:
                        print("Retries exhausted. Returning fallback value.")
                        if fallback is not None:
                            return fallback

                        else:
                            raise
                # delay = 2.17**delay

        return wrapper

    return decorator


